<?xml version="1.0" ?>
<!-- =================================================================================== -->
<!-- |    This document was autogenerated by xacro from ./ur3e_robot.urdf.xacro        | -->
<!-- |    EDITING THIS FILE BY HAND IS NOT RECOMMENDED                                 | -->
<!-- =================================================================================== -->
<robot name="ur3e" xmlns:xacro="http://ros.org/wiki/xacro">
  <gazebo>
    <plugin filename="libgazebo_ros_control.so" name="ros_control">
      <!--robotNamespace>/</robotNamespace-->
      <!--robotSimType>gazebo_ros_control/DefaultRobotHWSim</robotSimType-->
    </plugin>
    <!--
    <plugin name="gazebo_ros_power_monitor_controller" filename="libgazebo_ros_power_monitor.so">
      <alwaysOn>true</alwaysOn>
      <updateRate>1.0</updateRate>
      <timeout>5</timeout>
      <powerStateTopic>power_state</powerStateTopic>
      <powerStateRate>10.0</powerStateRate>
      <fullChargeCapacity>87.78</fullChargeCapacity>
      <dischargeRate>-474</dischargeRate>
      <chargeRate>525</chargeRate>
      <dischargeVoltage>15.52</dischargeVoltage>
      <chargeVoltage>16.41</chargeVoltage>
    </plugin>
-->
  </gazebo>
  <!--
  Author: Felix Messmer
-->
  <!-- measured from model -->
  <link name="base_link">
    <visual>
      <origin rpy="0 0 3.14159265359" xyz="0 0 0"/>
      <geometry>
        <mesh filename="package://ur_e_description/meshes/ur3e/visual/base.dae"/>
      </geometry>
      <material name="LightGrey">
        <color rgba="0.7 0.7 0.7 1.0"/>
      </material>
    </visual>
    <collision>
      <origin rpy="0 0 3.14159265359" xyz="0 0 0"/>
      <geometry>
        <mesh filename="package://ur_e_description/meshes/ur3e/collision/base.stl"/>
      </geometry>
    </collision>
    <inertial>
      <mass value="2.0"/>
      <origin rpy="0 0 0" xyz="0.0 0.0 0.0"/>
      <inertia ixx="0.0030531654454" ixy="0.0" ixz="0.0" iyy="0.0030531654454" iyz="0.0" izz="0.005625"/>
    </inertial>
  </link>
  <joint name="shoulder_pan_joint" type="revolute">
    <parent link="base_link"/>
    <child link="shoulder_link"/>
    <origin rpy="0 0 3.14159297124" xyz="0 0 0.151591275663"/>
    <axis xyz="0 0 1"/>
    <limit effort="330.0" lower="-6.28318530718" upper="6.28318530718" velocity="3.14"/>
    <dynamics damping="0.0" friction="0.0"/>
  </joint>
  <link name="shoulder_link">
    <visual>
      <origin rpy="0 0 3.14159265359" xyz="0 0 0"/>
      <geometry>
        <mesh filename="package://ur_e_description/meshes/ur3e/visual/shoulder.dae"/>
      </geometry>
      <material name="LightGrey">
        <color rgba="0.7 0.7 0.7 1.0"/>
      </material>
    </visual>
    <collision>
      <origin rpy="0 0 3.14159265359" xyz="0 0 0"/>
      <geometry>
        <mesh filename="package://ur_e_description/meshes/ur3e/collision/shoulder.stl"/>
      </geometry>
    </collision>
    <inertial>
      <mass value="2.0"/>
      <origin rpy="0 0 0" xyz="0.0 0.0 0.0"/>
      <inertia ixx="0.0080931634294" ixy="0.0" ixz="0.0" iyy="0.0080931634294" iyz="0.0" izz="0.005625"/>
    </inertial>
  </link>
  <joint name="shoulder_lift_joint" type="revolute">
    <parent link="shoulder_link"/>
    <child link="upper_arm_link"/>
    <origin rpy="1.57008236343 0 9.72792840537e-06" xyz="-9.32783264461e-05 0 0"/>
    <axis xyz="0 0 1"/>
    <limit effort="330.0" lower="-6.28318530718" upper="6.28318530718" velocity="3.14"/>
    <dynamics damping="0.0" friction="0.0"/>
  </joint>
  <link name="upper_arm_link">
    <visual>
      <origin rpy="1.57079632679 0 -1.57079632679" xyz="0 0 0.12"/>
      <geometry>
        <mesh filename="package://ur_e_description/meshes/ur3e/visual/upperarm.dae"/>
      </geometry>
      <material name="LightGrey">
        <color rgba="0.7 0.7 0.7 1.0"/>
      </material>
    </visual>
    <collision>
      <origin rpy="1.57079632679 0 -1.57079632679" xyz="0 0 0.12"/>
      <geometry>
        <mesh filename="package://ur_e_description/meshes/ur3e/collision/upperarm.stl"/>
      </geometry>
    </collision>
    <inertial>
      <mass value="3.42"/>
      <origin rpy="0 1.57079632679 0" xyz="-0.121873162961 0.0 0.12"/>
      <inertia ixx="0.0217418636525" ixy="0.0" ixz="0.0" iyy="0.0217418636525" iyz="0.0" izz="0.00961875"/>
    </inertial>
  </link>
  <joint name="elbow_joint" type="revolute">
    <parent link="upper_arm_link"/>
    <child link="forearm_link"/>
    <origin rpy="3.13889669648 3.1394450528 3.14157553155" xyz="-0.243746325923 0 0"/>
    <axis xyz="0 0 1"/>
    <limit effort="150.0" lower="-3.14159265359" upper="3.14159265359" velocity="3.14"/>
    <dynamics damping="0.0" friction="0.0"/>
  </joint>
  <link name="forearm_link">
    <visual>
      <origin rpy="1.57079632679 0 -1.57079632679" xyz="0 0 0.027"/>
      <geometry>
        <mesh filename="package://ur_e_description/meshes/ur3e/visual/forearm.dae"/>
      </geometry>
      <material name="LightGrey">
        <color rgba="0.7 0.7 0.7 1.0"/>
      </material>
    </visual>
    <collision>
      <origin rpy="1.57079632679 0 -1.57079632679" xyz="0 0 0.027"/>
      <geometry>
        <mesh filename="package://ur_e_description/meshes/ur3e/collision/forearm.stl"/>
      </geometry>
    </collision>
    <inertial>
      <mass value="1.26"/>
      <origin rpy="0 1.57079632679 0" xyz="-0.121873162961 0.0 0.027"/>
      <inertia ixx="0.00653322724176" ixy="0.0" ixz="0.0" iyy="0.00653322724176" iyz="0.0" izz="0.00354375"/>
    </inertial>
  </link>
  <joint name="wrist_1_joint" type="revolute">
    <parent link="forearm_link"/>
    <child link="wrist_1_link"/>
    <origin rpy="0.00750098624527 0.000417023234307 1.5779934395e-05" xyz="-0.212946558354 -0.000983354710539 0.13109426355"/>
    <axis xyz="0 0 1"/>
    <limit effort="54.0" lower="-6.28318530718" upper="6.28318530718" velocity="6.28"/>
    <dynamics damping="0.0" friction="0.0"/>
  </joint>
  <link name="wrist_1_link">
    <visual>
      <origin rpy="1.57079632679 0 0" xyz="0 0 -0.104"/>
      <geometry>
        <mesh filename="package://ur_e_description/meshes/ur3e/visual/wrist1.dae"/>
      </geometry>
      <material name="LightGrey">
        <color rgba="0.7 0.7 0.7 1.0"/>
      </material>
    </visual>
    <collision>
      <origin rpy="1.57079632679 0 0" xyz="0 0 -0.104"/>
      <geometry>
        <mesh filename="package://ur_e_description/meshes/ur3e/collision/wrist1.stl"/>
      </geometry>
    </collision>
    <inertial>
      <mass value="0.8"/>
      <origin rpy="0 0 0" xyz="0.0 0.0 0.0"/>
      <inertia ixx="0.00161032060861" ixy="0.0" ixz="0.0" iyy="0.00161032060861" iyz="0.0" izz="0.00225"/>
    </inertial>
  </link>
  <joint name="wrist_2_joint" type="revolute">
    <parent link="wrist_1_link"/>
    <child link="wrist_2_link"/>
    <origin rpy="1.5722928534 0 5.41797589164e-06" xyz="9.13566112809e-05 -0.0853218541233 -0.000127686520102"/>
    <axis xyz="0 0 1"/>
    <limit effort="54.0" lower="-6.28318530718" upper="6.28318530718" velocity="6.28"/>
    <dynamics damping="0.0" friction="0.0"/>
  </joint>
  <link name="wrist_2_link">
    <visual>
      <origin rpy="0 0 0" xyz="0 0 -0.08535"/>
      <geometry>
        <mesh filename="package://ur_e_description/meshes/ur3e/visual/wrist2.dae"/>
      </geometry>
      <material name="LightGrey">
        <color rgba="0.7 0.7 0.7 1.0"/>
      </material>
    </visual>
    <collision>
      <origin rpy="0 0 0" xyz="0 0 -0.08535"/>
      <geometry>
        <mesh filename="package://ur_e_description/meshes/ur3e/collision/wrist2.stl"/>
      </geometry>
    </collision>
    <inertial>
      <mass value="0.8"/>
      <origin rpy="0 0 0" xyz="0.0 0.0 0.0"/>
      <inertia ixx="0.00168817023266" ixy="0.0" ixz="0.0" iyy="0.00168817023266" iyz="0.0" izz="0.00225"/>
    </inertial>
  </link>
  <joint name="wrist_3_joint" type="revolute">
    <parent link="wrist_2_link"/>
    <child link="wrist_3_link"/>
    <origin rpy="1.5696887065 3.14159265359 3.1415923227" xyz="-0.000204644187552 0.0919106284329 -0.000101802119305"/>
    <axis xyz="0 0 1"/>
    <limit effort="54.0" lower="-6.28318530718" upper="6.28318530718" velocity="6.28"/>
    <dynamics damping="0.0" friction="0.0"/>
  </joint>
  <link name="wrist_3_link">
    <visual>
      <origin rpy="1.57079632679 0 0" xyz="0 0 -0.0921"/>
      <geometry>
        <mesh filename="package://ur_e_description/meshes/ur3e/visual/wrist3.dae"/>
      </geometry>
      <material name="LightGrey">
        <color rgba="0.7 0.7 0.7 1.0"/>
      </material>
    </visual>
    <collision>
      <origin rpy="1.57079632679 0 0" xyz="0 0 -0.0921"/>
      <geometry>
        <mesh filename="package://ur_e_description/meshes/ur3e/collision/wrist3.stl"/>
      </geometry>
    </collision>
    <inertial>
      <mass value="0.35"/>
      <origin rpy="0 0 0" xyz="0.0 0.0 -0.025"/>
      <inertia ixx="0.000250104066625" ixy="0.0" ixz="0.0" iyy="0.000250104066625" iyz="0.0" izz="0.000354375"/>
    </inertial>
  </link>
  <joint name="ee_fixed_joint" type="fixed">
    <parent link="wrist_3_link"/>
    <child link="ee_link"/>
    <origin rpy="0.0 -1.57079632679 1.57079632679" xyz="0.0 0.0 0.0"/>
  </joint>
  <link name="ee_link">
    <collision>
      <geometry>
        <box size="0.01 0.01 0.01"/>
      </geometry>
      <origin rpy="0 0 0" xyz="-0.01 0 0"/>
    </collision>
  </link>
  <transmission name="shoulder_pan_trans">
    <type>transmission_interface/SimpleTransmission</type>
    <joint name="shoulder_pan_joint">
      <hardwareInterface>hardware_interface/PositionJointInterface</hardwareInterface>
    </joint>
    <actuator name="shoulder_pan_motor">
      <mechanicalReduction>1</mechanicalReduction>
    </actuator>
  </transmission>
  <transmission name="shoulder_lift_trans">
    <type>transmission_interface/SimpleTransmission</type>
    <joint name="shoulder_lift_joint">
      <hardwareInterface>hardware_interface/PositionJointInterface</hardwareInterface>
    </joint>
    <actuator name="shoulder_lift_motor">
      <mechanicalReduction>1</mechanicalReduction>
    </actuator>
  </transmission>
  <transmission name="elbow_trans">
    <type>transmission_interface/SimpleTransmission</type>
    <joint name="elbow_joint">
      <hardwareInterface>hardware_interface/PositionJointInterface</hardwareInterface>
    </joint>
    <actuator name="elbow_motor">
      <mechanicalReduction>1</mechanicalReduction>
    </actuator>
  </transmission>
  <transmission name="wrist_1_trans">
    <type>transmission_interface/SimpleTransmission</type>
    <joint name="wrist_1_joint">
      <hardwareInterface>hardware_interface/PositionJointInterface</hardwareInterface>
    </joint>
    <actuator name="wrist_1_motor">
      <mechanicalReduction>1</mechanicalReduction>
    </actuator>
  </transmission>
  <transmission name="wrist_2_trans">
    <type>transmission_interface/SimpleTransmission</type>
    <joint name="wrist_2_joint">
      <hardwareInterface>hardware_interface/PositionJointInterface</hardwareInterface>
    </joint>
    <actuator name="wrist_2_motor">
      <mechanicalReduction>1</mechanicalReduction>
    </actuator>
  </transmission>
  <transmission name="wrist_3_trans">
    <type>transmission_interface/SimpleTransmission</type>
    <joint name="wrist_3_joint">
      <hardwareInterface>hardware_interface/PositionJointInterface</hardwareInterface>
    </joint>
    <actuator name="wrist_3_motor">
      <mechanicalReduction>1</mechanicalReduction>
    </actuator>
  </transmission>
  <gazebo reference="shoulder_link">
    <selfCollide>true</selfCollide>
  </gazebo>
  <gazebo reference="upper_arm_link">
    <selfCollide>true</selfCollide>
  </gazebo>
  <gazebo reference="forearm_link">
    <selfCollide>true</selfCollide>
  </gazebo>
  <gazebo reference="wrist_1_link">
    <selfCollide>true</selfCollide>
  </gazebo>
  <gazebo reference="wrist_3_link">
    <selfCollide>true</selfCollide>
  </gazebo>
  <gazebo reference="wrist_2_link">
    <selfCollide>true</selfCollide>
  </gazebo>
  <gazebo reference="ee_link">
    <selfCollide>true</selfCollide>
  </gazebo>
  <!-- ROS base_link to UR 'Base' Coordinates transform -->
  <link name="base"/>
  <joint name="base_link-base_fixed_joint" type="fixed">
    <!-- NOTE: this rotation is only needed as long as base_link itself is
                 not corrected wrt the real robot (ie: rotated over 180
                 degrees)
      -->
    <origin rpy="0 0 -3.14159265359" xyz="0 0 0"/>
    <parent link="base_link"/>
    <child link="base"/>
  </joint>
  <!-- Frame coincident with all-zeros TCP on UR controller -->
  <link name="tool0"/>
  <joint name="wrist_3_link-tool0_fixed_joint" type="fixed">
    <origin rpy="0 0 0" xyz="0 0 0"/>
    <parent link="wrist_3_link"/>
    <child link="tool0"/>
  </joint>
  <link name="world"/>
  <joint name="world_joint" type="fixed">
    <parent link="world"/>
    <child link="base_link"/>
    <origin rpy="0.0 0.0 0.0" xyz="0.0 0.0 0.0"/>
  </joint>

  <joint name="gripper_base_joint" type="fixed">
    <parent link="tool0"/>
    <child link="gripper_base_link"/>
    <origin rpy="1.57079632679 -1.57079632679 0" xyz="0 0 0"/>
    <axis xyz="0 1 0"/>
    <limit effort="0" lower="0" upper="0" velocity="0"/>
  </joint>
  <link name="gripper_base_link">
    <visual>
      <geometry>
        <mesh filename="package://robotiq_85_description/meshes/visual/robotiq_85_base_link.dae"/>
      </geometry>
    </visual>
    <collision>
      <geometry>
        <mesh filename="package://robotiq_85_description/meshes/collision/robotiq_85_base_link.stl"/>
      </geometry>
    </collision>
    <inertial>
      <mass value="0.636951"/>
      <origin xyz="0.0 0.0 0.0"/>
      <inertia ixx="0.000380" ixy="0.000000" ixz="0.000000" iyx="0.000000" iyy="0.001110" iyz="0.000000" izx="0.000000" izy="0.000000" izz="0.001171"/>
    </inertial>
  </link>
  <gazebo reference="gripper_base_link">
    <implicitSpringDamper>1</implicitSpringDamper>
    <mu1>100000</mu1>
    <mu2>100000</mu2>
    <kp>100000000.0</kp>
    <kd>1.0</kd>
  </gazebo>
  <joint name="gripper_finger1_joint" type="revolute">
    <parent link="gripper_base_link"/>
    <child link="gripper_finger1_knuckle_link"/>
    <axis xyz="0 0 1"/>
    <origin rpy="3.14159265359 0.0 0.0" xyz="0.05490451627 0.03060114443 0.0"/>
    <limit effort="100" lower="-0.0001" upper="0.0851" velocity="1000"/>
  </joint>
  <joint name="gripper_finger2_joint" type="revolute">
    <parent link="gripper_base_link"/>
    <child link="gripper_finger2_knuckle_link"/>
    <axis xyz="0 0 1"/>
    <origin rpy="0.0 0.0 0.0" xyz="0.05490451627 -0.03060114443 0.0"/>
    <limit effort="100" lower="-0.0001" upper="0.0851" velocity="1000"/>
    <mimic joint="gripper_finger1_joint"/>
  </joint>

  <link name="gripper_finger1_knuckle_link">
    <visual>
      <geometry>
        <mesh filename="package://robotiq_85_description/meshes/visual/robotiq_85_knuckle_link.dae"/>
      </geometry>
    </visual>
    <collision>
      <geometry>
        <mesh filename="package://robotiq_85_description/meshes/collision/robotiq_85_knuckle_link.stl"/>
      </geometry>
    </collision>
    <inertial>
      <mass value="0.018491"/>
      <origin xyz="0.0 0.0 0.0"/>
      <inertia ixx="0.000009" ixy="-0.000001" ixz="0.000000" iyx="-0.000001" iyy="0.000001" iyz="0.000000" izx="0.000000" izy="0.000000" izz="0.000010"/>
    </inertial>
  </link>
  <gazebo reference="gripper_finger1_knuckle_link">
    <implicitSpringDamper>1</implicitSpringDamper>
    <mu1>100000</mu1>
    <mu2>100000</mu2>
    <kp>100000000.0</kp>
    <kd>1.0</kd>
  </gazebo>
  <link name="gripper_finger2_knuckle_link">
    <visual>
      <geometry>
        <mesh filename="package://robotiq_85_description/meshes/visual/robotiq_85_knuckle_link.dae"/>
      </geometry>
    </visual>
    <collision>
      <geometry>
        <mesh filename="package://robotiq_85_description/meshes/collision/robotiq_85_knuckle_link.stl"/>
      </geometry>
    </collision>
    <inertial>
      <mass value="0.018491"/>
      <origin xyz="0.0 0.0 0.0"/>
      <inertia ixx="0.000009" ixy="-0.000001" ixz="0.000000" iyx="-0.000001" iyy="0.000001" iyz="0.000000" izx="0.000000" izy="0.000000" izz="0.000010"/>
    </inertial>
  </link>
  <gazebo reference="gripper_finger2_knuckle_link">
    <implicitSpringDamper>1</implicitSpringDamper>
    <mu1>100000</mu1>
    <mu2>100000</mu2>
    <kp>100000000.0</kp>
    <kd>1.0</kd>
  </gazebo>
  <joint name="gripper_finger1_finger_joint" type="fixed">
    <parent link="gripper_finger1_knuckle_link"/>
    <child link="gripper_finger1_finger_link"/>
    <origin rpy="0 0 0" xyz="-0.00408552455 -0.03148604435 0.0"/>
  </joint>
  <joint name="gripper_finger2_finger_joint" type="fixed">
    <parent link="gripper_finger2_knuckle_link"/>
    <child link="gripper_finger2_finger_link"/>
    <origin rpy="0 0 0" xyz="-0.00408552455 -0.03148604435 0.0"/>
  </joint>
  <link name="gripper_finger1_finger_link">
    <visual>
      <geometry>
        <mesh filename="package://robotiq_85_description/meshes/visual/robotiq_85_finger_link.dae"/>
      </geometry>
    </visual>
    <collision>
      <geometry>
        <mesh filename="package://robotiq_85_description/meshes/collision/robotiq_85_finger_link.stl"/>
      </geometry>
    </collision>
    <inertial>
      <mass value="0.027309"/>
      <origin xyz="0.0 0.0 0.0"/>
      <inertia ixx="0.000003" ixy="-0.000002" ixz="0.000000" iyx="-0.000002" iyy="0.000021" iyz="0.000000" izx="0.000000" izy="0.000000" izz="0.000020"/>
    </inertial>
  </link>
  <gazebo reference="gripper_finger1_finger_link">
    <implicitSpringDamper>1</implicitSpringDamper>
    <mu1>100000</mu1>
    <mu2>100000</mu2>
    <kp>100000000.0</kp>
    <kd>1.0</kd>
  </gazebo>
  <link name="gripper_finger2_finger_link">
    <visual>
      <geometry>
        <mesh filename="package://robotiq_85_description/meshes/visual/robotiq_85_finger_link.dae"/>
      </geometry>
    </visual>
    <collision>
      <geometry>
        <mesh filename="package://robotiq_85_description/meshes/collision/robotiq_85_finger_link.stl"/>
      </geometry>
    </collision>
    <inertial>
      <mass value="0.027309"/>
      <origin xyz="0.0 0.0 0.0"/>
      <inertia ixx="0.000003" ixy="-0.000002" ixz="0.000000" iyx="-0.000002" iyy="0.000021" iyz="0.000000" izx="0.000000" izy="0.000000" izz="0.000020"/>
    </inertial>
  </link>
  <gazebo reference="gripper_finger2_finger_link">
    <implicitSpringDamper>1</implicitSpringDamper>
    <mu1>100000</mu1>
    <mu2>100000</mu2>
    <kp>100000000.0</kp>
    <kd>1.0</kd>
  </gazebo>
  <joint name="gripper_finger1_inner_knuckle_joint" type="continuous">
    <parent link="gripper_base_link"/>
    <child link="gripper_finger1_inner_knuckle_link"/>
    <axis xyz="0 0 1"/>
    <origin rpy="3.14159265359 0.0 0.0" xyz="0.06142 0.0127 0"/>
    <limit effort="0.1" lower="-3.14" upper="3.14" velocity="100.0"/>
    <mimic joint="gripper_finger1_joint" offset="0"/>
  </joint>
  <joint name="gripper_finger2_inner_knuckle_joint" type="continuous">
    <parent link="gripper_base_link"/>
    <child link="gripper_finger2_inner_knuckle_link"/>
    <axis xyz="0 0 1"/>
    <origin rpy="0 0 0" xyz="0.06142 -0.0127 0"/>
    <limit effort="0.1" lower="-3.14" upper="3.14" velocity="100.0"/>
    <mimic joint="gripper_finger1_joint" offset="0"/>
  </joint>
  <link name="gripper_finger1_inner_knuckle_link">
    <visual>
      <geometry>
        <mesh filename="package://robotiq_85_description/meshes/visual/robotiq_85_inner_knuckle_link.dae"/>
      </geometry>
    </visual>
    <collision>
      <geometry>
        <mesh filename="package://robotiq_85_description/meshes/collision/robotiq_85_inner_knuckle_link.stl"/>
      </geometry>
    </collision>
    <inertial>
      <mass value="0.029951"/>
      <origin xyz="0.0 0.0 0.0"/>
      <inertia ixx="0.000039" ixy="0.000000" ixz="0.000000" iyx="0.000000" iyy="0.000005" iyz="0.000000" izx="0.000000" izy="0.000000" izz="0.000035"/>
    </inertial>
  </link>
  <gazebo reference="gripper_finger1_inner_knuckle_link">
    <implicitSpringDamper>1</implicitSpringDamper>
    <mu1>100000</mu1>
    <mu2>100000</mu2>
    <kp>100000000.0</kp>
    <kd>1.0</kd>
  </gazebo>
  <link name="gripper_finger2_inner_knuckle_link">
    <visual>
      <geometry>
        <mesh filename="package://robotiq_85_description/meshes/visual/robotiq_85_inner_knuckle_link.dae"/>
      </geometry>
    </visual>
    <collision>
      <geometry>
        <mesh filename="package://robotiq_85_description/meshes/collision/robotiq_85_inner_knuckle_link.stl"/>
      </geometry>
    </collision>
    <inertial>
      <mass value="0.029951"/>
      <origin xyz="0.0 0.0 0.0"/>
      <inertia ixx="0.000039" ixy="0.000000" ixz="0.000000" iyx="0.000000" iyy="0.000005" iyz="0.000000" izx="0.000000" izy="0.000000" izz="0.000035"/>
    </inertial>
  </link>
  <gazebo reference="gripper_finger2_inner_knuckle_link">
    <implicitSpringDamper>1</implicitSpringDamper>
    <mu1>100000</mu1>
    <mu2>100000</mu2>
    <kp>100000000.0</kp>
    <kd>1.0</kd>
  </gazebo>
  <joint name="gripper_finger1_finger_tip_joint" type="continuous">
    <parent link="gripper_finger1_inner_knuckle_link"/>
    <child link="gripper_finger1_finger_tip_link"/>
    <axis xyz="0 0 1"/>
    <origin rpy="0.0 0.0 0.0" xyz="0.04303959807 -0.03759940821 0.0"/>
    <limit effort="0.1" lower="-3.14" upper="3.14" velocity="100.0"/>
    <mimic joint="gripper_finger1_joint" multiplier="-1"/>
  </joint>
  <joint name="gripper_finger2_finger_tip_joint" type="continuous">
    <parent link="gripper_finger2_inner_knuckle_link"/>
    <child link="gripper_finger2_finger_tip_link"/>
    <axis xyz="0 0 1"/>
    <origin rpy="0.0 0.0 0.0" xyz="0.04303959807 -0.03759940821  0.0"/>
    <limit effort="0.1" lower="-3.14" upper="3.14" velocity="100.0"/>
    <mimic joint="gripper_finger1_joint" multiplier="-1"/>
  </joint>
  <link name="gripper_finger1_finger_tip_link">
    <visual>
      <geometry>
        <mesh filename="package://robotiq_85_description/meshes/visual/robotiq_85_finger_tip_link.dae"/>
      </geometry>
    </visual>
    <collision>
      <geometry>
        <mesh filename="package://robotiq_85_description/meshes/collision/robotiq_85_finger_tip_link.stl"/>
      </geometry>
    </collision>
    <inertial>
      <mass value="0.019555"/>
      <origin xyz="0.0 0.0 0.0"/>
      <inertia ixx="0.000002" ixy="0.000000" ixz="0.000000" iyx="0.000000" iyy="0.000005" iyz="0.000000" izx="0.000000" izy="0.000000" izz="0.000006"/>
    </inertial>
  </link>
  <gazebo reference="gripper_finger1_finger_tip_link">
    <implicitSpringDamper>1</implicitSpringDamper>
    <mu1>100000</mu1>
    <mu2>100000</mu2>
    <kp>100000000.0</kp>
    <kd>1.0</kd>
  </gazebo>
  <link name="gripper_finger2_finger_tip_link">
    <visual>
      <geometry>
        <mesh filename="package://robotiq_85_description/meshes/visual/robotiq_85_finger_tip_link.dae"/>
      </geometry>
    </visual>
    <collision>
      <geometry>
        <mesh filename="package://robotiq_85_description/meshes/collision/robotiq_85_finger_tip_link.stl"/>
      </geometry>
    </collision>
    <inertial>
      <mass value="0.019555"/>
      <origin xyz="0.0 0.0 0.0"/>
      <inertia ixx="0.000002" ixy="0.000000" ixz="0.000000" iyx="0.000000" iyy="0.000005" iyz="0.000000" izx="0.000000" izy="0.000000" izz="0.000006"/>
    </inertial>
  </link>
  <gazebo reference="gripper_finger2_finger_tip_link">
    <implicitSpringDamper>1</implicitSpringDamper>
    <mu1>100000</mu1>
    <mu2>100000</mu2>
    <kp>100000000.0</kp>
    <kd>1.0</kd>
  </gazebo>
  <transmission name="gripper_finger1_trans">
    <type>transmission_interface/SimpleTransmission</type>
    <joint name="gripper_finger1_joint">
      <hardwareInterface>PositionJointInterface</hardwareInterface>
    </joint>
    <actuator name="gripper_finger1_motor">
      <mechanicalReduction>1</mechanicalReduction>
      <hardwareInterface>PositionJointInterface</hardwareInterface>
    </actuator>
  </transmission>
  <gazebo>
    <!-- loading plugin: mimic joints works in gazebo now -->
    <plugin filename="libroboticsgroup_gazebo_mimic_joint_plugin.so" name="mimic_robotiq_85_1">
      <joint>gripper_finger1_joint</joint>
      <mimicJoint>gripper_finger2_joint</mimicJoint>
      <!--multiplier>1.0</multiplier>
                <offset>0.0</offset-->
    </plugin>
    <plugin filename="libroboticsgroup_gazebo_mimic_joint_plugin.so" name="mimic_robotiq_85_2">
      <joint>gripper_finger1_joint</joint>
      <mimicJoint>gripper_finger2_inner_knuckle_joint</mimicJoint>
      <!--multiplier>1.0</multiplier>
                <offset>0.0</offset-->
    </plugin>
    <plugin filename="libroboticsgroup_gazebo_mimic_joint_plugin.so" name="mimic_robotiq_85_3">
      <joint>gripper_finger1_joint</joint>
      <mimicJoint>gripper_finger1_inner_knuckle_joint</mimicJoint>
      <!--multiplier>1.0</multiplier>
                <offset>0.0</offset-->
    </plugin>
    <plugin filename="libroboticsgroup_gazebo_mimic_joint_plugin.so" name="mimic_robotiq_85_4">
      <joint>gripper_finger1_joint</joint>
      <mimicJoint>gripper_finger1_finger_tip_joint</mimicJoint>
      <multiplier>-1.0</multiplier>
      <offset>0.0</offset>
    </plugin>
    <plugin filename="libroboticsgroup_gazebo_mimic_joint_plugin.so" name="mimic_robotiq_85_5">
      <joint>gripper_finger1_joint</joint>
      <mimicJoint>gripper_finger2_finger_tip_joint</mimicJoint>
      <multiplier>-1.0</multiplier>
      <offset>0.0</offset>
    </plugin>
  </gazebo>
</robot>
